# This file is @generated, regenerate by re-running test with `-- --env BUCK2_UPDATE_GOLDEN=1` appended to the test command

{
  "failures": {
    "root//fail_action:fail_many_with_error_handler": "Action failed: root//fail_action:fail_many_with_error_handler (<unspecified>) (fail_many_with_error_handler1)\nLocal command returned non-zero exit code 1\nLocal command: env -- 'BUCK_SCRATCH_PATH=buck-out/v2/tmp/root/<HASH>/fail_many_with_error_handler1' python3 fail_action/fail_indent.py buck-out/v2/gen/root/<HASH>/fail_action/__fail_many_with_error_handler__/fail_indent.py\nStdout: <empty>\nStderr:\n  File \"fail_action/fail_indent.py\", line 10\n    j = 2\n    ^\nIndentationError: unexpected indent\n\nAction sub-errors produced by error handlers:\n- [indentation] Indentation error!\n"
  },
  "results": {
    "root//fail_action:fail_many_with_error_handler": {
      "configured": {
        "<unspecified>": {
          "configured_graph_size": null,
          "errors": [
            {
              "action_error": {
                "digest": "<DIGEST>",
                "error_content": "<STRING_HASH>",
                "error_diagnostics": {
                  "sub_errors": [
                    {
                      "category": "syntax",
                      "locations": [
                        {
                          "file": "not_really_the_right_file",
                          "line": 1
                        }
                      ],
                      "message_content": "<STRING_HASH>"
                    }
                  ]
                },
                "key": {
                  "owner": "root//fail_action:fail_many_with_error_handler (<unspecified>)"
                },
                "name": {
                  "category": "fail_many_with_error_handler0",
                  "identifier": ""
                },
                "stderr_content": "<STRING_HASH>",
                "stdout_content": "<STRING_HASH>"
              },
              "cause_index": 0,
              "error_tags": [
                "ACTION_COMMAND_FAILURE",
                "ANY_ACTION_EXECUTION"
              ],
              "message_content": "<STRING_HASH>"
            },
            {
              "action_error": {
                "digest": "<DIGEST>",
                "error_content": "<STRING_HASH>",
                "error_diagnostics": {
                  "sub_errors": [
                    {
                      "category": "indentation",
                      "locations": null,
                      "message_content": "<STRING_HASH>"
                    }
                  ]
                },
                "key": {
                  "owner": "root//fail_action:fail_many_with_error_handler (<unspecified>)"
                },
                "name": {
                  "category": "fail_many_with_error_handler1",
                  "identifier": ""
                },
                "stderr_content": "<STRING_HASH>",
                "stdout_content": "<STRING_HASH>"
              },
              "cause_index": 1,
              "error_tags": [
                "ACTION_COMMAND_FAILURE",
                "ANY_ACTION_EXECUTION"
              ],
              "message_content": "<STRING_HASH>"
            }
          ],
          "other_outputs": {},
          "outputs": {},
          "success": "FAIL"
        }
      },
      "configured_graph_size": null,
      "errors": [],
      "other_outputs": {},
      "outputs": {},
      "success": "FAIL"
    }
  },
  "strings": {
    "<STRING_HASH>": "",
    "<STRING_HASH>": "  File \"fail_action/fail_compile.py\", line 9\n    does not compile\n             ^\nSyntaxError: invalid syntax\n",
    "<STRING_HASH>": "  File \"fail_action/fail_indent.py\", line 10\n    j = 2\n    ^\nIndentationError: unexpected indent\n",
    "<STRING_HASH>": "Action failed: root//fail_action:fail_many_with_error_handler (<unspecified>) (fail_many_with_error_handler0)\nLocal command returned non-zero exit code 1\nLocal command: env -- 'BUCK_SCRATCH_PATH=buck-out/v2/tmp/root/<HASH>/fail_many_with_error_handler0' python3 fail_action/fail_compile.py buck-out/v2/gen/root/<HASH>/fail_action/__fail_many_with_error_handler__/fail_compile.py\nStdout: <empty>\nStderr:\n  File \"fail_action/fail_compile.py\", line 9\n    does not compile\n             ^\nSyntaxError: invalid syntax\n\nAction sub-errors produced by error handlers:\n- [syntax] Syntax error!\n",
    "<STRING_HASH>": "Action failed: root//fail_action:fail_many_with_error_handler (<unspecified>) (fail_many_with_error_handler1)\nLocal command returned non-zero exit code 1\nLocal command: env -- 'BUCK_SCRATCH_PATH=buck-out/v2/tmp/root/<HASH>/fail_many_with_error_handler1' python3 fail_action/fail_indent.py buck-out/v2/gen/root/<HASH>/fail_action/__fail_many_with_error_handler__/fail_indent.py\nStdout: <empty>\nStderr:\n  File \"fail_action/fail_indent.py\", line 10\n    j = 2\n    ^\nIndentationError: unexpected indent\n\nAction sub-errors produced by error handlers:\n- [indentation] Indentation error!\n",
    "<STRING_HASH>": "Indentation error!",
    "<STRING_HASH>": "Local command returned non-zero exit code 1",
    "<STRING_HASH>": "Syntax error!"
  },
  "success": false,
  "truncated": false
}
